2024-06-02 22:18:53.620133: I tensorflow/core/util/port.cc:113] oneDNN custom operations are on. You may see slightly different numerical results due to floating-point round-off errors from different computation orders. To turn them off, set the environment variable `TF_ENABLE_ONEDNN_OPTS=0`.
2024-06-02 22:18:54.477313: I tensorflow/core/util/port.cc:113] oneDNN custom operations are on. You may see slightly different numerical results due to floating-point round-off errors from different computation orders. To turn them off, set the environment variable `TF_ENABLE_ONEDNN_OPTS=0`.
2024-06-02 22:18:57.062298: I tensorflow/core/platform/cpu_feature_guard.cc:210] This TensorFlow binary is optimized to use available CPU instructions in performance-critical operations.
To enable the following instructions: AVX2 FMA, in other operations, rebuild TensorFlow with the appropriate compiler flags.
C:\Users\Nicol\AppData\Local\Programs\Python\Python312\Lib\site-packages\keras\src\layers\rnn\rnn.py:204: UserWarning: Do not pass an `input_shape`/`input_dim` argument to a layer. When using Sequential models, prefer using an `Input(shape)` object as the first layer in the model instead.
  super().__init__(**kwargs)
Traceback (most recent call last):
  File "C:\Users\Nicol\AppData\Local\Programs\Python\Python312\Lib\site-packages\py4j\java_gateway.py", line 2231, in start
    self.server_socket.bind((self.address, self.port))
OSError: [WinError 10048] Solo se permite un uso de cada dirección de socket (protocolo/dirección de red/puerto)

During handling of the above exception, another exception occurred:

Traceback (most recent call last):
  File "C:\Users\Nicol\OneDrive\Escritorio\restricciones\PP2Backend\inicio.py", line 273, in <module>
    main()
  File "C:\Users\Nicol\OneDrive\Escritorio\restricciones\PP2Backend\inicio.py", line 236, in main
    start_gateway(modeloLatitude,modeloLongitude,scale1,scale2)
  File "C:\Users\Nicol\OneDrive\Escritorio\restricciones\PP2Backend\inicio.py", line 264, in start_gateway
    gateway = JavaGateway(
              ^^^^^^^^^^^^
  File "C:\Users\Nicol\AppData\Local\Programs\Python\Python312\Lib\site-packages\py4j\java_gateway.py", line 1838, in __init__
    self.start_callback_server(self.callback_server_parameters)
  File "C:\Users\Nicol\AppData\Local\Programs\Python\Python312\Lib\site-packages\py4j\java_gateway.py", line 1914, in start_callback_server
    self._callback_server.start()
  File "C:\Users\Nicol\AppData\Local\Programs\Python\Python312\Lib\site-packages\py4j\java_gateway.py", line 2240, in start
    raise Py4JNetworkError(msg, e)
py4j.protocol.Py4JNetworkError: An error occurred while trying to start the callback server (127.0.0.1:25334)
